<mujoco model="abb_irb14000">
    <compiler angle="radian" meshdir="stl" texturedir="textures" />
    <visual>
        <quality shadowsize="1000"/>
        <headlight ambient="0.4 0.4 0.4" diffuse="0.5 0.5 0.5" specular="0.8 0.8 0.8" />
    </visual>
    <option timestep="0.001" gravity="0 0 -9.81" iterations="100" integrator="Euler" cone="elliptic"  />
    <!-- Copied from PR2 model in GPS. This was necessary to get natural behaviour -->
    <default>
        <joint armature="0.04" damping="1.0" limited="true" margin="0.01" />
        <geom friction=".5" margin="0.001"/>
    </default>
    <size njmax="500" nconmax="100" />
    <contact>
        <!-- For some reason these links collide -->
        <exclude body1="yumi_base_link" body2="left_link_1" />
        <exclude body1="yumi_base_link" body2="right_link_1" />

        <!-- Link 5 and 7 sometimes collide, not sure if this can actually happen or not -->
        <exclude body1="left_link_5" body2="left_link_7" />
        <exclude body1="right_link_5" body2="right_link_7" />
    </contact>
    <asset>
        <mesh name="base_link_v" file="base_link_v.stl" />
        <mesh name="base_link_c" file="base_link_c.stl" />
        <mesh name="left_link_1_v" file="left_link_1_v.stl" />
        <mesh name="left_link_1_c" file="left_link_1_c.stl" />
        <mesh name="left_link_2_v" file="left_link_2_v.stl" />
        <mesh name="left_link_2_c" file="left_link_2_c.stl" />
        <mesh name="left_link_3_v" file="left_link_3_v.stl" />
        <mesh name="left_link_3_c" file="left_link_3_c.stl" />
        <mesh name="left_link_4_v" file="left_link_4_v.stl" />
        <mesh name="left_link_4_c" file="left_link_4_c.stl" />
        <mesh name="left_link_5_v" file="left_link_5_v.stl" />
        <mesh name="left_link_5_c" file="left_link_5_c.stl" />
        <mesh name="left_link_6_v" file="left_link_6_v.stl" />
        <mesh name="left_link_6_c" file="left_link_6_c.stl" />
        <mesh name="left_link_7_v" file="left_link_7_v.stl" />
        <mesh name="left_link_7_c" file="left_link_7_c.stl" />
        <mesh name="right_link_1_v" file="right_link_1_v.stl" />
        <mesh name="right_link_1_c" file="right_link_1_c.stl" />
        <mesh name="right_link_2_v" file="right_link_2_v.stl" />
        <mesh name="right_link_2_c" file="right_link_2_c.stl" />
        <mesh name="right_link_3_v" file="right_link_3_v.stl" />
        <mesh name="right_link_3_c" file="right_link_3_c.stl" />
        <mesh name="right_link_4_v" file="right_link_4_v.stl" />
        <mesh name="right_link_4_c" file="right_link_4_c.stl" />
        <mesh name="right_link_5_v" file="right_link_5_v.stl" />
        <mesh name="right_link_5_c" file="right_link_5_c.stl" />
        <mesh name="right_link_6_v" file="right_link_6_v.stl" />
        <mesh name="right_link_6_c" file="right_link_6_c.stl" />
        <mesh name="right_link_7_v" file="right_link_7_v.stl" />
        <mesh name="right_link_7_c" file="right_link_7_c.stl" />
        <mesh name="smart_gripper_v" file="smart_gripper_v.stl" />
        <mesh name="smart_gripper_c" file="smart_gripper_c.stl" />
        <!--texture type="skybox" file="nightsky.png" gridsize="3 4" gridlayout=".U..LFRB.D.."/-->
        <texture type="skybox" builtin="gradient" width="100" height="100" rgb1="1 1 1" rgb2="0.8 0.8 1" />
        <texture builtin="flat" height="1278" mark="cross" markrgb="1 1 1" name="texgeom" random="0.01" rgb1="0.8 0.6 0.4" rgb2="0.8 0.6 0.4" type="cube" width="127"/>
        <texture builtin="checker" height="100" name="texplane" rgb1="0 0 0" rgb2="0.8 0.8 0.8" type="2d" width="100"/>
        <material name="geom" texture="texgeom" texuniform="true"/>
    </asset>
    <worldbody>
        <!-- ======================Adding lighting (why is it inside worldbody?)======================== -->
        <!--light cutoff="45" diffuse="0.3 0.3 0.3" dir="-1 -1 -1" directional="true" exponent="10" pos="2 2 2" specular=".8 .8 .8"/>
        <light diffuse="0.7 0.7 0.7" directional="false" exponent="10" pos="2 2 2" /-->

        <!--light diffuse="0.5 0.5 0.5" pos="2 2 2" exponent="10" target="table" mode="fixed"/-->
        <light name="extra" dir="0 0 -1" pos="2 2 5" exponent="5" />
        <!-- ======================Adding robot model======================== -->
        <body name="yumi_base_link" pos="0 0 0.04">
            <inertial pos="-0.172194 -0.000976297 0.164215" quat="0.704188 -0.0569853 -0.0576709 0.705369" mass="64.4428" diaginertia="2.55006 2.13906 1.29867" />
            <geom type="mesh" rgba="0.6 0.6 0.6 1" mesh="base_link_v" />
            <body name="left_link_1" pos="0.02767 0.06163 0.39997">
                <inertial pos="0.0617695 0.0491119 0.0334395" quat="0.586161 0.5945 -0.548003 0.051744" mass="1.68707" diaginertia="0.00596178 0.00577134 0.00264552" />
                <joint name="yumi_joint_1_l" pos="0 0 0" axis="0.813782 0.342033 0.469864" limited="true" range="-2.92343 2.92343" damping="1.06"/>
                <geom type="mesh" mesh="left_link_1_v" />
                <body name="left_link_2" pos="0.09359 0.08563 0.0565">
                    <inertial pos="0.0575266 -0.0189548 0.0551795" quat="0.162142 0.532845 0.336916 0.759127" mass="2.25401" diaginertia="0.0112842 0.0110497 0.00382165" />
                    <joint name="yumi_joint_2_l" pos="0 0 0" axis="0.107006 0.706538 -0.699538" limited="true" range="-2.48709 0.741765" damping="1.09"/>
                    <geom type="mesh" rgba="0.6 0.6 0.6 1" mesh="left_link_2_v" />
                    <body name="left_link_3" pos="0.11922 0.00381 0.06637">
                        <inertial pos="0.0853618 0.0318821 0.016909" quat="-0.320902 0.735319 -0.166055 0.57337" mass="1.14796" diaginertia="0.00330713 0.00319694 0.00134163" />
                        <joint name="yumi_joint_7_l" pos="0 0 0" axis="0.813771 0.34207 0.469856" limited="true" range="-2.92343 2.92343" damping="0.61"/>
                        <geom type="mesh" mesh="left_link_3_v" />
                        <body name="left_link_4" pos="0.12649 0.0436 0.00883">
                            <inertial pos="0.0437221 -0.0662985 0.0140473" quat="0.257268 0.862184 0.115159 0.420939" mass="1.83034" diaginertia="0.00817669 0.00792384 0.0026734" />
                            <joint name="yumi_joint_3_l" pos="0 0 0" axis="0.106857 0.706733 -0.699364" limited="true" range="-2.13803 1.37881" damping="0.08" />
                            <geom type="mesh" rgba="0.6 0.6 0.6 1" mesh="left_link_4_v" />
                            <body name="left_link_5" pos="0.10366 -0.09418 -0.0248">
                                <inertial pos="0.0400559 -0.0378699 -0.0616318" quat="0.430142 -0.233314 0.0691526 0.869345" mass="0.683703" diaginertia="0.00168259 0.00161801 0.00050124" />
                                <joint name="yumi_joint_4_l" pos="0 0 0" axis="0.571257 -0.619307 -0.538631" limited="true" range="-5.044 5.044" damping="0.08" />
                                <geom type="mesh" mesh="left_link_5_v" />
                                <body name="left_link_6" pos="0.05912 -0.0626 -0.11428">
                                    <inertial pos="-0.00162091 -0.024941 0.0472062" quat="0.602883 0.429918 -0.517116 0.429294" mass="0.606118" diaginertia="0.000766064 0.000724189 0.000688628" />
                                    <joint name="yumi_joint_5_l" pos="0 0 0" axis="0.106863 0.706797 -0.699298" limited="true" range="-1.51844 2.3911" damping="0.08" />
                                    <geom type="mesh" rgba="0.6 0.6 0.6 1" mesh="left_link_6_v" />
                                    <body name="left_link_7" pos="0.01635 -0.01921 0.04313">
                                        <inertial pos="0.0148469 -0.0155979 -0.0142907" quat="0.470194 0.048331 -0.389545 0.790466" mass="0.0721865" diaginertia="2.40347e-05 2.01222e-05 1.96282e-05" />
                                        <joint name="yumi_joint_6_l" pos="0 0 0" axis="0.57121 -0.619367 -0.538612" limited="true" range="-3.97935 3.97935" damping="0.1" />
                                        <geom type="mesh" mesh="left_link_7_v" />
                                        <body name="left_tool0" pos="0.02173 -0.02341 -0.02059" quat="0.297586 -0.0673761 0.874618 -0.376758">
                                            <inertial pos="0.02173 -0.02341 -0.02059" quat="0.297586 -0.0673761 0.874618 -0.376758" mass="0" diaginertia="0 0 0" />
                                            <body name="left_gripper_base" pos="0 0 0">
                                                <inertial pos="1.20154e-05 0.00242304 0.0527266" quat="0.706871 0.00701907 -0.0072129 0.707271" mass="0.563549" diaginertia="0.00101254 0.000796983 0.000496939" />
                                                <geom type="mesh" rgba="0.6 0.6 0.6 1" mesh="smart_gripper_v" />
                                            </body>
                                        </body>
                                    </body>
                                </body>
                            </body>
                        </body>
                    </body>
                </body>
            </body>
            <body name="right_link_1" pos="0.02767 -0.06163 0.39997">
                <inertial pos="0.0579499 -0.0237766 0.0585117" quat="0.888611 0.00706116 0.284115 -0.359999" mass="1.68708" diaginertia="0.00596179 0.00577136 0.00264553" />
                <joint name="yumi_joint_1_r" pos="0 0 0" axis="0.813782 -0.342033 0.469864" limited="true" range="-2.92343 2.92343" damping="1.06" />
                <geom type="mesh" mesh="right_link_1_v" />
                <body name="right_link_2" pos="0.08697 -0.04182 0.09986">
                    <inertial pos="0.0673887 -0.0458319 -0.00894338" quat="0.789632 0.235697 0.454133 0.338661" mass="2.25414" diaginertia="0.0112853 0.0110502 0.00382215" />
                    <joint name="yumi_joint_2_r" pos="0 0 0" axis="-0.107006 0.706538 0.699538" limited="true" range="-2.48709 0.741765" damping="1.09" />
                    <geom type="mesh" rgba="0.6 0.6 0.6 1" mesh="right_link_2_v" />
                    <body name="right_link_3" pos="0.12136 -0.04574 0.02043">
                        <inertial pos="0.0841711 -0.00546401 0.046357" quat="0.221398 0.457214 0.28036 0.814454" mass="1.17909" diaginertia="0.00350236 0.00337992 0.00139159" />
                        <joint name="yumi_joint_7_r" pos="0 0 0" axis="0.813782 -0.342123 0.469799" limited="true" range="-2.92343 2.92343" damping="0.61" />
                        <geom type="mesh" mesh="right_link_3_v" />
                        <body name="right_link_4" pos="0.12282 0.00844 0.06476">
                            <inertial pos="0.0548802 -0.00721442 -0.0586922" quat="0.40553 0.120895 0.776964 0.466108" mass="1.83037" diaginertia="0.00817678 0.00792391 0.00267348" />
                            <joint name="yumi_joint_3_r" pos="0 0 0" axis="-0.106857 0.706733 0.699364" limited="true" range="-2.13803 1.37881" damping="0.08"/>
                            <geom type="mesh" rgba="0.6 0.6 0.6 1" mesh="right_link_4_v" />
                            <body name="right_link_5" pos="0.11181 0.04026 -0.07815">
                                <inertial pos="0.0356561 0.0670094 -0.0327934" quat="0.70858 0.584035 0.128687 -0.37451" mass="0.68372" diaginertia="0.00168264 0.00161801 0.000501278" />
                                <joint name="yumi_joint_4_r" pos="0 0 0" axis="0.571257 0.619307 -0.538631" limited="true" range="-5.044 5.044" damping="0.08" />
                                <geom type="mesh" mesh="right_link_5_v" />
                                <body name="right_link_6" pos="0.04951 0.12621 -0.05134">
                                    <inertial pos="0.00963643 -0.0499608 -0.0270555" quat="0.619994 -0.113325 0.143626 0.762979" mass="0.627544" diaginertia="0.000807004 0.000780265 0.000722194" />
                                    <joint name="yumi_joint_5_r" pos="0 0 0" axis="-0.106662 0.706635 0.699493" limited="true" range="-1.51844 2.3911" damping="0.08" />
                                    <geom type="mesh" rgba="0.6 0.6 0.6 1" mesh="right_link_6_v" />
                                    <body name="right_link_7" pos="0.02596 -0.0444 -0.01981">
                                        <inertial pos="0.0144296 0.0160357 -0.0132869" quat="0.201483 0.412494 -0.819005 0.344216" mass="0.0748575" diaginertia="2.59881e-05 2.12717e-05 2.08339e-05" />
                                        <joint name="yumi_joint_6_r" pos="0 0 0" axis="0.571393 0.619384 -0.538399" limited="true" range="-3.97935 3.97935" damping="0.1" />
                                        <geom type="mesh" mesh="right_link_7_v" />
                                        <body name="right_tool0" pos="0.02173 0.02341 -0.02059" quat="0.297586 0.0673761 0.874618 0.376758">
                                            <inertial pos="0.02173 0.02341 -0.02059" quat="0.297586 0.0673761 0.874618 0.376758" mass="0" diaginertia="0 0 0" />
                                            <body name="right_gripper_base" pos="0 0 0">
                                                <inertial pos="1.20154e-05 0.00242304 0.0527266" quat="0.706871 0.00701907 -0.0072129 0.707271" mass="0.563549" diaginertia="0.00101254 0.000796983 0.000496939" />
                                                <geom type="mesh" rgba="0.6 0.6 0.6 1" mesh="smart_gripper_v" />
                                            </body>
                                        </body>
                                    </body>
                                </body>
                            </body>
                        </body>
                    </body>
                </body>
            </body>
        </body>

    </worldbody>

    <actuator>
        <velocity name="yumi_joint_1_l" ctrllimited="true" ctrlrange="-3.14159265359 3.14159265359" joint="yumi_joint_1_l" kv="1" />
        <velocity name="yumi_joint_2_l" ctrllimited="true" ctrlrange="-3.14159265359 3.14159265359" joint="yumi_joint_2_l" kv="1" />
        <velocity name="yumi_joint_7_l" ctrllimited="true" ctrlrange="-3.14159265359 3.14159265359" joint="yumi_joint_7_l" kv="1" />
        <velocity name="yumi_joint_3_l" ctrllimited="true" ctrlrange="-3.14159265359 3.14159265359" joint="yumi_joint_3_l" kv="1" />
        <velocity name="yumi_joint_4_l" ctrllimited="true" ctrlrange="-6.98131700798 6.98131700798" joint="yumi_joint_4_l" kv="1" />
        <velocity name="yumi_joint_5_l" ctrllimited="true" ctrlrange="-6.98131700798 6.98131700798" joint="yumi_joint_5_l" kv="1" />
        <velocity name="yumi_joint_6_l" ctrllimited="true" ctrlrange="-6.98131700798 6.98131700798" joint="yumi_joint_6_l" kv="1" />

        <velocity name="yumi_joint_1_r" ctrllimited="true" ctrlrange="-3.14159265359 3.14159265359" joint="yumi_joint_1_r" kv="1" />
        <velocity name="yumi_joint_2_r" ctrllimited="true" ctrlrange="-3.14159265359 3.14159265359" joint="yumi_joint_2_r" kv="1" />
        <velocity name="yumi_joint_7_r" ctrllimited="true" ctrlrange="-3.14159265359 3.14159265359" joint="yumi_joint_7_r" kv="1" />
        <velocity name="yumi_joint_3_r" ctrllimited="true" ctrlrange="-3.14159265359 3.14159265359" joint="yumi_joint_3_r" kv="1" />
        <velocity name="yumi_joint_4_r" ctrllimited="true" ctrlrange="-6.98131700798 6.98131700798" joint="yumi_joint_4_r" kv="1" />
        <velocity name="yumi_joint_5_r" ctrllimited="true" ctrlrange="-6.98131700798 6.98131700798" joint="yumi_joint_5_r" kv="1" />
        <velocity name="yumi_joint_6_r" ctrllimited="true" ctrlrange="-6.98131700798 6.98131700798" joint="yumi_joint_6_r" kv="1" />
    </actuator>
</mujoco>
